<?xml version="1.0" ?>
<sdf version="1.5">
  <model name='hinged_door_ticket'>
      <static>0</static>
      <link name='frame'>
        <pose frame=''>0.06 -0.0005 0 0 -0 0</pose>
        <visual name='visual'>
          <pose frame=''>0 -0.06858 0 0 -0 0</pose>
          <geometry>
            <mesh>
              <uri>model://hinged_door/meshes/frame.dae</uri>
            </mesh>
          </geometry> 
        </visual>
        <inertial>
          <mass>1</mass>
        </inertial>
      </link>
      <model name='sub_door'>
	  <static>0</static>
	  <link name='door'>
	    <pose frame=''>-0 0 2.04 3.14159 -0 1.58</pose>
	    <inertial>
	      <mass>10.3256</mass>
	      <pose frame=''>0.4569 0.0349 1.016 0 -0 0</pose>
	    </inertial>
	    <collision name='collision'>
	      <pose frame=''>0.4569 0.0349 1.016 0 -0 0</pose>
	      <geometry>
		<box>
		  <size>0.9144 0.04445 2.032</size>
		</box>
	      </geometry>
	      <max_contacts>10</max_contacts>
	      <surface>
		<contact>
		  <ode/>
		</contact>
		<bounce/>
		<friction>
		  <torsional>
		    <ode/>
		  </torsional>
		  <ode/>
		</friction>
	      </surface>
	    </collision>
	    <visual name='visual'>
	      <pose frame=''>0 -0.06858 0 0 -0 0</pose>
	      <geometry>
		<mesh>
		  <uri>model://hinged_door/meshes/door.dae</uri>
		</mesh>
	      </geometry>
	    </visual>
	    <sensor name='my_contact' type='contact'>
	      <contact>
		<collision>collision</collision>
		<topic>__default_topic__</topic>
	      </contact>
	      <update_rate>1</update_rate>
	    </sensor>
	    <self_collide>0</self_collide>
	    <enable_wind>0</enable_wind>
	    <kinematic>0</kinematic>
	  </link>
      </model>

      <joint name='hinge' type='revolute'>
        <parent>frame</parent>
        <child>sub_door::door</child>
        <axis>
          <xyz>0 0 1</xyz>
          <initial_position>1.5</initial_position>
          <limit>
            <lower>0</lower>
            <upper>1.58</upper>
          </limit>
          <dynamics>
            <damping>1</damping>
            <friction>1</friction>
            <spring_reference>0</spring_reference>
            <spring_stiffness>0</spring_stiffness>
          </dynamics>
          <use_parent_model_frame>1</use_parent_model_frame>
        </axis>
        <physics>
          <ode>
            <cfm_damping>1</cfm_damping>
            <limit>
              <cfm>0</cfm>
              <erp>0.2</erp>
            </limit>
          </ode>
        </physics>
      </joint>
      <joint name='world_joint' type='revolute'>
        <child>frame</child>
        <parent>world</parent>
        <axis>
          <limit>
            <lower>0</lower>
            <upper>0</upper>
          </limit>
          <xyz>0 1 0</xyz>
          <dynamics>
            <damping>1</damping>
            <spring_reference>0</spring_reference>
            <spring_stiffness>0</spring_stiffness>
          </dynamics>
          <use_parent_model_frame>1</use_parent_model_frame>
        </axis>
        <physics>
          <ode>
            <cfm_damping>1</cfm_damping>
            <limit>
              <cfm>0</cfm>
              <erp>0.2</erp>
            </limit>
          </ode>
        </physics>
      </joint>
      <pose frame=''>-1.40403 -0.190259 0 0 -0 0.5</pose>
    </model>
</sdf>
